Workbook

Sheet Uso
A1: Simulador de precios y descuentos
A2: Valores monetarios en $ según los archivos originales. Importes por bulto salvo indicación.
A4: Parámetro / concepto | B4: Valor / explicación
A5: Recargo observado sobre Precio Base | B5: 0.03
A6: Decimales del precio calculado | B6: 3
A7: Modelo de descuento | B7: Proporcional: se supone que el precio completo baja en el mismo porcentaje. Pendiente de validar.
A8: Cómo usar | B8: En Simulador, completar SKU, vencimiento, cantidad de bultos y precio final deseado por unidad.
A9: Celdas editables | B9: Amarillo: entradas. El catálogo conserva los precios y unidades del segundo archivo.
A10: Precio actual calculado | B10: P. Final de lista + Precio Base × recargo observado. No sumar 3% al P. Final.
A11: Descuento requerido | B11: 1 − precio deseado por unidad × unidades por bulto / precio actual por bulto. Se muestra sin redondear el cálculo interno.
A12: Gasto del descuento | B12: Importe cedido frente al precio actual × bultos. No representa costo contable ni pérdida de margen.
A13: Alcance de la evidencia | B13: Los 10 SKU de muestra respaldan el recargo. Su aplicación a otros SKU es una extrapolación.
A14: Impuestos | B14: Los archivos no desglosan ni nombran los impuestos. No se asignó una identidad fiscal al recargo.
A15: Precisión | B15: La regla reproduce la muestra con diferencia máxima de $0,001 al redondear. El sistema puede redondear distinto.
A16: Fuente de precios | B16: 20260908091006plantillaPreciosColumna.xlsx · Lista Columnas · A:G · lista 5.
A17: Fuente de comparación | B17: export (74).xlsx · ag-grid · 10 SKU, 1 bulto y bonificación 0 en todos los casos.
A18: Frescura por sucursal | B18: Trelew y Madryn: una fila por lote informado. Prioridad visual ACCIONAR; se conservan los tres bloques de lotes.
... A24: Dónde ingresar el precio | B24: En Trelew o Madryn, columna F: precio final deseado por unidad. E: bultos a bonificar, hasta el stock del lote.

Sheet Simulador
A1: Simulador por SKU y lote
A2: Amarillo = completar. Precio deseado por unidad; cantidad en bultos. Descuento proporcional pendiente de validación.
A4: SKU | B4: Descripción | C4: Unidades por bulto | D4: Vencimiento | E4: Bultos a descontar | F4: Final deseado / unidad | G4: Final actual / bulto | H4: Descuento requerido | I4: Importe cedido / bulto | J4: Gasto total descuento | K4: Final deseado / bulto | L4: Estado
A5: 2218 | B5: =IF(A5="","",IF(COUNTIF(Catalogo!$A$5:$A$905,A5)=0,"SKU no encontrado",INDEX(Catalogo!$B$5:$B$905,MATCH(A5,Catalogo!$A$5:$A$905,0)))) -> QUILMES - 4X6 LAT 473 | C5: =IF(OR(A5="",B5="SKU no encontrado"),"",INDEX(Catalogo!$C$5:$C$905,MATCH(A5,Catalogo!$A$5:$A$905,0))) -> 24 | G5: =IF(OR(A5="",B5="SKU no encontrado"),"",IF(INDEX(Catalogo!$H$5:$H$905,MATCH(A5,Catalogo!$A$5:$A$905,0))=0,"",INDEX(Catalogo!$H$5:$H$905,MATCH(A5,Catalogo!$A$5:$A$905,0)))) -> 48405.919 | H5: =IF(OR(G5="",F5="",F5<0,C5<=0,F5*C5>G5),"",1-F5*C5/G5) | I5: =IF(H5="","",G5-F5*C5) | J5: =IF(OR(I5="",E5="",E5<=0),"",I5*E5) | K5: =IF(OR(H5="",C5<=0),"",F5*C5) | L5: =IF(A5="","",IF(B5="SKU no encontrado",B5,IF(G5="","Sin precio válido",IF(F5="","Completar precio deseado",IF(OR(F5<0,C5<=0,F5*C5>G5),"Revisar precio deseado",IF(OR(E5="",E5<=0),"Completar bultos","Estimado proporcional")))))) -> Completar precio deseado
A6: 19253 | B6: =IF(A6="","",IF(COUNTIF(Catalogo!$A$5:$A$905,A6)=0,"SKU no encontrado",INDEX(Catalogo!$B$5:$B$905,MATCH(A6,Catalogo!$A$5:$A$905,0)))) -> ANDES ORIGEN IPA RET X12 1000 | C6: =IF(OR(A6="",B6="SKU no encontrado"),"",INDEX(Catalogo!$C$5:$C$905,MATCH(A6,Catalogo!$A$5:$A$905,0))) -> 12 | G6: =IF(OR(A6="",B6="SKU no encontrado"),"",IF(INDEX(Catalogo!$H$5:$H$905,MATCH(A6,Catalogo!$A$5:$A$905,0))=0,"",INDEX(Catalogo!$H$5:$H$905,MATCH(A6,Catalogo!$A$5:$A$905,0)))) -> 50984.146 | H6: =IF(OR(G6="",F6="",F6<0,C6<=0,F6*C6>G6),"",1-F6*C6/G6) | I6: =IF(H6="","",G6-F6*C6) | J6: =IF(OR(I6="",E6="",E6<=0),"",I6*E6) | K6: =IF(OR(H6="",C6<=0),"",F6*C6) | L6: =IF(A6="","",IF(B6="SKU no encontrado",B6,IF(G6="","Sin precio válido",IF(F6="","Completar precio deseado",IF(OR(F6<0,C6<=0,F6*C6>G6),"Revisar precio deseado",IF(OR(E6="",E6<=0),"Completar bultos","Estimado proporcional")))))) -> Completar precio deseado
A7: 30645 | B7: =IF(A7="","",IF(COUNTIF(Catalogo!$A$5:$A$905,A7)=0,"SKU no encontrado",INDEX(Catalogo!$B$5:$B$905,MATCH(A7,Catalogo!$A$5:$A$905,0)))) -> PEPSI 70KCAL PET X8 2000CC | C7: =IF(OR(A7="",B7="SKU no encontrado"),"",INDEX(Catalogo!$C$5:$C$905,MATCH(A7,Catalogo!$A$5:$A$905,0))) -> 8 | G7: =IF(OR(A7="",B7="SKU no encontrado"),"",IF(INDEX(Catalogo!$H$5:$H$905,MATCH(A7,Catalogo!$A$5:$A$905,0))=0,"",INDEX(Catalogo!$H$5:$H$905,MATCH(A7,Catalogo!$A$5:$A$905,0)))) -> 29656.171 | H7: =IF(OR(G7="",F7="",F7<0,C7<=0,F7*C7>G7),"",1-F7*C7/G7) | I7: =IF(H7="","",G7-F7*C7) | J7: =IF(OR(I7="",E7="",E7<=0),"",I7*E7) | K7: =IF(OR(H7="",C7<=0),"",F7*C7) | L7: =IF(A7="","",IF(B7="SKU no encontrado",B7,IF(G7="","Sin precio válido",IF(F7="","Completar precio deseado",IF(OR(F7<0,C7<=0,F7*C7>G7),"Revisar precio deseado",IF(OR(E7="",E7<=0),"Completar bultos","Estimado proporcional")))))) -> Completar precio deseado
A8: 49807 | B8: =IF(A8="","",IF(COUNTIF(Catalogo!$A$5:$A$905,A8)=0,"SKU no encontrado",INDEX(Catalogo!$B$5:$B$905,MATCH(A8,Catalogo!$A$5:$A$905,0)))) -> STELLA PURE GOLD CAN 4X6 473CC T | C8: =IF(OR(A8="",B8="SKU no encontrado"),"",INDEX(Catalogo!$C$5:$C$905,MATCH(A8,Catalogo!$A$5:$A$905,0))) -> 24 | G8: =IF(OR(A8="",B8="SKU no encontrado"),"",IF(INDEX(Catalogo!$H$5:$H$905,MATCH(A8,Catalogo!$A$5:$A$905,0))=0,"",INDEX(Catalogo!$H$5:$H$905,MATCH(A8,Catalogo!$A$5:$A$905,0)))) -> 72010.181 | H8: =IF(OR(G8="",F8="",F8<0,C8<=0,F8*C8>G8),"",1-F8*C8/G8) | I8: =IF(H8="","",G8-F8*C8) | J8: =IF(OR(I8="",E8="",E8<=0),"",I8*E8) | K8: =IF(OR(H8="",C8<=0),"",F8*C8) | L8: =IF(A8="","",IF(B8="SKU no encontrado",B8,IF(G8="","Sin precio válido",IF(F8="","Completar precio deseado",IF(OR(F8<0,C8<=0,F8*C8>G8),"Revisar precio deseado",IF(OR(E8="",E8<=0),"Completar bultos","Estimado proporcional")))))) -> Completar precio deseado
A9: 24931 | B9: =IF(A9="","",IF(COUNTIF(Catalogo!$A$5:$A$905,A9)=0,"SKU no encontrado",INDEX(Catalogo!$B$5:$B$905,MATCH(A9,Catalogo!$A$5:$A$905,0)))) -> STELLA ART NOIRE PM CAN 4X6 473CC CART | C9: =IF(OR(A9="",B9="SKU no encontrado"),"",INDEX(Catalogo!$C$5:$C$905,MATCH(A9,Catalogo!$A$5:$A$905,0))) -> 24 | G9: =IF(OR(A9="",B9="SKU no encontrado"),"",IF(INDEX(Catalogo!$H$5:$H$905,MATCH(A9,Catalogo!$A$5:$A$905,0))=0,"",INDEX(Catalogo!$H$5:$H$905,MATCH(A9,Catalogo!$A$5:$A$905,0)))) -> 72010.181 | H9: =IF(OR(G9="",F9="",F9<0,C9<=0,F9*C9>G9),"",1-F9*C9/G9) | I9: =IF(H9="","",G9-F9*C9) | J9: =IF(OR(I9="",E9="",E9<=0),"",I9*E9) | K9: =IF(OR(H9="",C9<=0),"",F9*C9) | L9: =IF(A9="","",IF(B9="SKU no encontrado",B9,IF(G9="","Sin precio válido",IF(F9="","Completar precio deseado",IF(OR(F9<0,C9<=0,F9*C9>G9),"Revisar precio deseado",IF(OR(E9="",E9<=0),"Completar bultos","Estimado proporcional")))))) -> Completar precio deseado
A10: 31434 | B10: =IF(A10="","",IF(COUNTIF(Catalogo!$A$5:$A$905,A10)=0,"SKU no encontrado",INDEX(Catalogo!$B$5:$B$905,MATCH(A10,Catalogo!$A$5:$A$905,0)))) -> BRAHMA CAN 4X4 710CC | C10: =IF(OR(A10="",B10="SKU no encontrado"),"",INDEX(Catalogo!$C$5:$C$905,MATCH(A10,Catalogo!$A$5:$A$905,0))) -> 16 | G10: =IF(OR(A10="",B10="SKU no encontrado"),"",IF(INDEX(Catalogo!$H$5:$H$905,MATCH(A10,Catalogo!$A$5:$A$905,0))=0,"",INDEX(Catalogo!$H$5:$H$905,MATCH(A10,Catalogo!$A$5:$A$905,0)))) -> 44562.415 | H10: =IF(OR(G10="",F10="",F10<0,C10<=0,F10*C10>G10),"",1-F10*C10/G10) | I10: =IF(H10="","",G10-F10*C10) | J10: =IF(OR(I10="",E10="",E10<=0),"",I10*E10) | K10: =IF(OR(H10="",C10<=0),"",F10*C10) | L10: =IF(A10="","",IF(B10="SKU no encontrado",B10,IF(G10="","Sin precio válido",IF(F10="","Completar precio deseado",IF(OR(F10<0,C10<=0,F10*C10>G10),"Revisar precio deseado",IF(OR(E10="",E10<=0),"Completar bultos","Estimado proporcional")))))) -> Completar precio deseado
A11: 591 | B11: =IF(A11="","",IF(COUNTIF(Catalogo!$A$5:$A$905,A11)=0,"SKU no encontrado",INDEX(Catalogo!$B$5:$B$905,MATCH(A11,Catalogo!$A$5:$A$905,0)))) -> MIRINDA MANZANA * X8 PET2250 | C11: =IF(OR(A11="",B11="SKU no encontrado"),"",INDEX(Catalogo!$C$5:$C$905,MATCH(A11,Catalogo!$A$5:$A$905,0))) -> 8 | G11: =IF(OR(A11="",B11="SKU no encontrado"),"",IF(INDEX(Catalogo!$H$5:$H$905,MATCH(A11,Catalogo!$A$5:$A$905,0))=0,"",INDEX(Catalogo!$H$5:$H$905,MATCH(A11,Catalogo!$A$5:$A$905,0)))) -> 19048.439 | H11: =IF(OR(G11="",F11="",F11<0,C11<=0,F11*C11>G11),"",1-F11*C11/G11) | I11: =IF(H11="","",G11-F11*C11) | J11: =IF(OR(I11="",E11="",E11<=0),"",I11*E11) | K11: =IF(OR(H11="",C11<=0),"",F11*C11) | L11: =IF(A11="","",IF(B11="SKU no encontrado",B11,IF(G11="","Sin precio válido",IF(F11="","Completar precio deseado",IF(OR(F11<0,C11<=0,F11*C11>G11),"Revisar precio deseado",IF(OR(E11="",E11<=0),"Completar bultos","Estimado proporcional")))))) -> Completar precio deseado
A12: 16371 | B12: =IF(A12="","",IF(COUNTIF(Catalogo!$A$5:$A$905,A12)=0,"SKU no encontrado",INDEX(Catalogo!$B$5:$B$905,MATCH(A12,Catalogo!$A$5:$A$905,0)))) -> RED BULL CAN 6X4 250 | C12: =IF(OR(A12="",B12="SKU no encontrado"),"",INDEX(Catalogo!$C$5:$C$905,MATCH(A12,Catalogo!$A$5:$A$905,0))) -> 24 | G12: =IF(OR(A12="",B12="SKU no encontrado"),"",IF(INDEX(Catalogo!$H$5:$H$905,MATCH(A12,Catalogo!$A$5:$A$905,0))=0,"",INDEX(Catalogo!$H$5:$H$905,MATCH(A12,Catalogo!$A$5:$A$905,0)))) -> 65853.251 | H12: =IF(OR(G12="",F12="",F12<0,C12<=0,F12*C12>G12),"",1-F12*C12/G12) | I12: =IF(H12="","",G12-F12*C12) | J12: =IF(OR(I12="",E12="",E12<=0),"",I12*E12) | K12: =IF(OR(H12="",C12<=0),"",F12*C12) | L12: =IF(A12="","",IF(B12="SKU no encontrado",B12,IF(G12="","Sin precio válido",IF(F12="","Completar precio deseado",IF(OR(F12<0,C12<=0,F12*C12>G12),"Revisar precio deseado",IF(OR(E12="",E12<=0),"Completar bultos","Estimado proporcional")))))) -> Completar precio deseado
A13: 22185 | B13: =IF(A13="","",IF(COUNTIF(Catalogo!$A$5:$A$905,A13)=0,"SKU no encontrado",INDEX(Catalogo!$B$5:$B$905,MATCH(A13,Catalogo!$A$5:$A$905,0)))) -> GLACIAR SG PET X6 750 222 PC | C13: =IF(OR(A13="",B13="SKU no encontrado"),"",INDEX(Catalogo!$C$5:$C$905,MATCH(A13,Catalogo!$A$5:$A$905,0))) -> 6 | G13: =IF(OR(A13="",B13="SKU no encontrado"),"",IF(INDEX(Catalogo!$H$5:$H$905,MATCH(A13,Catalogo!$A$5:$A$905,0))=0,"",INDEX(Catalogo!$H$5:$H$905,MATCH(A13,Catalogo!$A$5:$A$905,0)))) -> 10016.943 | H13: =IF(OR(G13="",F13="",F13<0,C13<=0,F13*C13>G13),"",1-F13*C13/G13) | I13: =IF(H13="","",G13-F13*C13) | J13: =IF(OR(I13="",E13="",E13<=0),"",I13*E13) | K13: =IF(OR(H13="",C13<=0),"",F13*C13) | L13: =IF(A13="","",IF(B13="SKU no encontrado",B13,IF(G13="","Sin precio válido",IF(F13="","Completar precio deseado",IF(OR(F13<0,C13<=0,F13*C13>G13),"Revisar precio deseado",IF(OR(E13="",E13<=0),"Completar bultos","Estimado proporcional")))))) -> Completar precio deseado
A14: 1416 | B14: =IF(A14="","",IF(COUNTIF(Catalogo!$A$5:$A$905,A14)=0,"SKU no encontrado",INDEX(Catalogo!$B$5:$B$905,MATCH(A14,Catalogo!$A$5:$A$905,0)))) -> GATORADE MANZANA * X6 PET 500 | C14: =IF(OR(A14="",B14="SKU no encontrado"),"",INDEX(Catalogo!$C$5:$C$905,MATCH(A14,Catalogo!$A$5:$A$905,0))) -> 6 | G14: =IF(OR(A14="",B14="SKU no encontrado"),"",IF(INDEX(Catalogo!$H$5:$H$905,MATCH(A14,Catalogo!$A$5:$A$905,0))=0,"",INDEX(Catalogo!$H$5:$H$905,MATCH(A14,Catalogo!$A$5:$A$905,0)))) -> 12591.147 | H14: =IF(OR(G14="",F14="",F14<0,C14<=0,F14*C14>G14),"",1-F14*C14/G14) | I14: =IF(H14="","",G14-F14*C14) | J14: =IF(OR(I14="",E14="",E14<=0),"",I14*E14) | K14: =IF(OR(H14="",C14<=0),"",F14*C14) | L14: =IF(A14="","",IF(B14="SKU no encontrado",B14,IF(G14="","Sin precio válido",IF(F14="","Completar precio deseado",IF(OR(F14<0,C14<=0,F14*C14>G14),"Revisar precio deseado",IF(OR(E14="",E14<=0),"Completar bultos","Estimado proporcional")))))) -> Completar precio deseado
B15: =IF(A15="","",IF(COUNTIF(Catalogo!$A$5:$A$905,A15)=0,"SKU no encontrado",INDEX(Catalogo!$B$5:$B$905,MATCH(A15,Catalogo!$A$5:$A$905,0)))) | C15: =IF(OR(A15="",B15="SKU no encontrado"),"",INDEX(Catalogo!$C$5:$C$905,MATCH(A15,Catalogo!$A$5:$A$905,0))) | G15: =IF(OR(A15="",B15="SKU no encontrado"),"",IF(INDEX(Catalogo!$H$5:$H$905,MATCH(A15,Catalogo!$A$5:$A$905,0))=0,"",INDEX(Catalogo!$H$5:$H$905,MATCH(A15,Catalogo!$A$5:$A$905,0)))) | H15: =IF(OR(G15="",F15="",F15<0,C15<=0,F15*C15>G15),"",1-F15*C15/G15) -> #VALUE! | I15: =IF(H15="","",G15-F15*C15) -> #VALUE! | J15: =IF(OR(I15="",E15="",E15<=0),"",I15*E15) -> #VALUE! | K15: =IF(OR(H15="",C15<=0),"",F15*C15) -> #VALUE! | L15: =IF(A15="","",IF(B15="SKU no encontrado",B15,IF(G15="","Sin precio válido",IF(F15="","Completar precio deseado",IF(OR(F15<0,C15<=0,F15*C15>G15),"Revisar precio deseado",IF(OR(E15="",E15<=0),"Completar bultos","Estimado proporcional"))))))
B16: =IF(A16="","",IF(COUNTIF(Catalogo!$A$5:$A$905,A16)=0,"SKU no encontrado",INDEX(Catalogo!$B$5:$B$905,MATCH(A16,Catalogo!$A$5:$A$905,0)))) | C16: =IF(OR(A16="",B16="SKU no encontrado"),"",INDEX(Catalogo!$C$5:$C$905,MATCH(A16,Catalogo!$A$5:$A$905,0))) | G16: =IF(OR(A16="",B16="SKU no encontrado"),"",IF(INDEX(Catalogo!$H$5:$H$905,MATCH(A16,Catalogo!$A$5:$A$905,0))=0,"",INDEX(Catalogo!$H$5:$H$905,MATCH(A16,Catalogo!$A$5:$A$905,0)))) | H16: =IF(OR(G16="",F16="",F16<0,C16<=0,F16*C16>G16),"",1-F16*C16/G16) -> #VALUE! | I16: =IF(H16="","",G16-F16*C16) -> #VALUE! | J16: =IF(OR(I16="",E16="",E16<=0),"",I16*E16) -> #VALUE! | K16: =IF(OR(H16="",C16<=0),"",F16*C16) -> #VALUE! | L16: =IF(A16="","",IF(B16="SKU no encontrado",B16,IF(G16="","Sin precio válido",IF(F16="","Completar precio deseado",IF(OR(F16<0,C16<=0,F16*C16>G16),"Revisar precio deseado",IF(OR(E16="",E16<=0),"Completar bultos","Estimado proporcional"))))))
B17: =IF(A17="","",IF(COUNTIF(Catalogo!$A$5:$A$905,A17)=0,"SKU no encontrado",INDEX(Catalogo!$B$5:$B$905,MATCH(A17,Catalogo!$A$5:$A$905,0)))) | C17: =IF(OR(A17="",B17="SKU no encontrado"),"",INDEX(Catalogo!$C$5:$C$905,MATCH(A17,Catalogo!$A$5:$A$905,0))) | G17: =IF(OR(A17="",B17="SKU no encontrado"),"",IF(INDEX(Catalogo!$H$5:$H$905,MATCH(A17,Catalogo!$A$5:$A$905,0))=0,"",INDEX(Catalogo!$H$5:$H$905,MATCH(A17,Catalogo!$A$5:$A$905,0)))) | H17: =IF(OR(G17="",F17="",F17<0,C17<=0,F17*C17>G17),"",1-F17*C17/G17) -> #VALUE! | I17: =IF(H17="","",G17-F17*C17) -> #VALUE! | J17: =IF(OR(I17="",E17="",E17<=0),"",I17*E17) -> #VALUE! | K17: =IF(OR(H17="",C17<=0),"",F17*C17) -> #VALUE! | L17: =IF(A17="","",IF(B17="SKU no encontrado",B17,IF(G17="","Sin precio válido",IF(F17="","Completar precio deseado",IF(OR(F17<0,C17<=0,F17*C17>G17),"Revisar precio deseado",IF(OR(E17="",E17<=0),"Completar bultos","Estimado proporcional"))))))
B18: =IF(A18="","",IF(COUNTIF(Catalogo!$A$5:$A$905,A18)=0,"SKU no encontrado",INDEX(Catalogo!$B$5:$B$905,MATCH(A18,Catalogo!$A$5:$A$905,0)))) | C18: =IF(OR(A18="",B18="SKU no encontrado"),"",INDEX(Catalogo!$C$5:$C$905,MATCH(A18,Catalogo!$A$5:$A$905,0))) | G18: =IF(OR(A18="",B18="SKU no encontrado"),"",IF(INDEX(Catalogo!$H$5:$H$905,MATCH(A18,Catalogo!$A$5:$A$905,0))=0,"",INDEX(Catalogo!$H$5:$H$905,MATCH(A18,Catalogo!$A$5:$A$905,0)))) | H18: =IF(OR(G18="",F18="",F18<0,C18<=0,F18*C18>G18),"",1-F18*C18/G18) -> #VALUE! | I18: =IF(H18="","",G18-F18*C18) -> #VALUE! | J18: =IF(OR(I18="",E18="",E18<=0),"",I18*E18) -> #VALUE! | K18: =IF(OR(H18="",C18<=0),"",F18*C18) -> #VALUE! | L18: =IF(A18="","",IF(B18="SKU no encontrado",B18,IF(G18="","Sin precio válido",IF(F18="","Completar precio deseado",IF(OR(F18<0,C18<=0,F18*C18>G18),"Revisar precio deseado",IF(OR(E18="",E18<=0),"Completar bultos","Estimado proporcional"))))))
B19: =IF(A19="","",IF(COUNTIF(Catalogo!$A$5:$A$905,A19)=0,"SKU no encontrado",INDEX(Catalogo!$B$5:$B$905,MATCH(A19,Catalogo!$A$5:$A$905,0)))) | C19: =IF(OR(A19="",B19="SKU no encontrado"),"",INDEX(Catalogo!$C$5:$C$905,MATCH(A19,Catalogo!$A$5:$A$905,0))) | G19: =IF(OR(A19="",B19="SKU no encontrado"),"",IF(INDEX(Catalogo!$H$5:$H$905,MATCH(A19,Catalogo!$A$5:$A$905,0))=0,"",INDEX(Catalogo!$H$5:$H$905,MATCH(A19,Catalogo!$A$5:$A$905,0)))) | H19: =IF(OR(G19="",F19="",F19<0,C19<=0,F19*C19>G19),"",1-F19*C19/G19) -> #VALUE! | I19: =IF(H19="","",G19-F19*C19) -> #VALUE! | J19: =IF(OR(I19="",E19="",E19<=0),"",I19*E19) -> #VALUE! | K19: =IF(OR(H19="",C19<=0),"",F19*C19) -> #VALUE! | L19: =IF(A19="","",IF(B19="SKU no encontrado",B19,IF(G19="","Sin precio válido",IF(F19="","Completar precio deseado",IF(OR(F19<0,C19<=0,F19*C19>G19),"Revisar precio deseado",IF(OR(E19="",E19<=0),"Completar bultos","Estimado proporcional"))))))
B20: =IF(A20="","",IF(COUNTIF(Catalogo!$A$5:$A$905,A20)=0,"SKU no encontrado",INDEX(Catalogo!$B$5:$B$905,MATCH(A20,Catalogo!$A$5:$A$905,0)))) | C20: =IF(OR(A20="",B20="SKU no encontrado"),"",INDEX(Catalogo!$C$5:$C$905,MATCH(A20,Catalogo!$A$5:$A$905,0))) | G20: =IF(OR(A20="",B20="SKU no encontrado"),"",IF(INDEX(Catalogo!$H$5:$H$905,MATCH(A20,Catalogo!$A$5:$A$905,0))=0,"",INDEX(Catalogo!$H$5:$H$905,MATCH(A20,Catalogo!$A$5:$A$905,0)))) | H20: =IF(OR(G20="",F20="",F20<0,C20<=0,F20*C20>G20),"",1-F20*C20/G20) -> #VALUE! | I20: =IF(H20="","",G20-F20*C20) -> #VALUE! | J20: =IF(OR(I20="",E20="",E20<=0),"",I20*E20) -> #VALUE! | K20: =IF(OR(H20="",C20<=0),"",F20*C20) -> #VALUE! | L20: =IF(A20="","",IF(B20="SKU no encontrado",B20,IF(G20="","Sin precio válido",IF(F20="","Completar precio deseado",IF(OR(F20<0,C20<=0,F20*C20>G20),"Revisar precio deseado",IF(OR(E20="",E20<=0),"Completar bultos","Estimado proporcional"))))))
B21: =IF(A21="","",IF(COUNTIF(Catalogo!$A$5:$A$905,A21)=0,"SKU no encontrado",INDEX(Catalogo!$B$5:$B$905,MATCH(A21,Catalogo!$A$5:$A$905,0)))) | C21: =IF(OR(A21="",B21="SKU no encontrado"),"",INDEX(Catalogo!$C$5:$C$905,MATCH(A21,Catalogo!$A$5:$A$905,0))) | G21: =IF(OR(A21="",B21="SKU no encontrado"),"",IF(INDEX(Catalogo!$H$5:$H$905,MATCH(A21,Catalogo!$A$5:$A$905,0))=0,"",INDEX(Catalogo!$H$5:$H$905,MATCH(A21,Catalogo!$A$5:$A$905,0)))) | H21: =IF(OR(G21="",F21="",F21<0,C21<=0,F21*C21>G21),"",1-F21*C21/G21) -> #VALUE! | I21: =IF(H21="","",G21-F21*C21) -> #VALUE! | J21: =IF(OR(I21="",E21="",E21<=0),"",I21*E21) -> #VALUE! | K21: =IF(OR(H21="",C21<=0),"",F21*C21) -> #VALUE! | L21: =IF(A21="","",IF(B21="SKU no encontrado",B21,IF(G21="","Sin precio válido",IF(F21="","Completar precio deseado",IF(OR(F21<0,C21<=0,F21*C21>G21),"Revisar precio deseado",IF(OR(E21="",E21<=0),"Completar bultos","Estimado proporcional"))))))
B22: =IF(A22="","",IF(COUNTIF(Catalogo!$A$5:$A$905,A22)=0,"SKU no encontrado",INDEX(Catalogo!$B$5:$B$905,MATCH(A22,Catalogo!$A$5:$A$905,0)))) | C22: =IF(OR(A22="",B22="SKU no encontrado"),"",INDEX(Catalogo!$C$5:$C$905,MATCH(A22,Catalogo!$A$5:$A$905,0))) | G22: =IF(OR(A22="",B22="SKU no encontrado"),"",IF(INDEX(Catalogo!$H$5:$H$905,MATCH(A22,Catalogo!$A$5:$A$905,0))=0,"",INDEX(Catalogo!$H$5:$H$905,MATCH(A22,Catalogo!$A$5:$A$905,0)))) | H22: =IF(OR(G22="",F22="",F22<0,C22<=0,F22*C22>G22),"",1-F22*C22/G22) -> #VALUE! | I22: =IF(H22="","",G22-F22*C22) -> #VALUE! | J22: =IF(OR(I22="",E22="",E22<=0),"",I22*E22) -> #VALUE! | K22: =IF(OR(H22="",C22<=0),"",F22*C22) -> #VALUE! | L22: =IF(A22="","",IF(B22="SKU no encontrado",B22,IF(G22="","Sin precio válido",IF(F22="","Completar precio deseado",IF(OR(F22<0,C22<=0,F22*C22>G22),"Revisar precio deseado",IF(OR(E22="",E22<=0),"Completar bultos","Estimado proporcional"))))))
B23: =IF(A23="","",IF(COUNTIF(Catalogo!$A$5:$A$905,A23)=0,"SKU no encontrado",INDEX(Catalogo!$B$5:$B$905,MATCH(A23,Catalogo!$A$5:$A$905,0)))) | C23: =IF(OR(A23="",B23="SKU no encontrado"),"",INDEX(Catalogo!$C$5:$C$905,MATCH(A23,Catalogo!$A$5:$A$905,0))) | G23: =IF(OR(A23="",B23="SKU no encontrado"),"",IF(INDEX(Catalogo!$H$5:$H$905,MATCH(A23,Catalogo!$A$5:$A$905,0))=0,"",INDEX(Catalogo!$H$5:$H$905,MATCH(A23,Catalogo!$A$5:$A$905,0)))) | H23: =IF(OR(G23="",F23="",F23<0,C23<=0,F23*C23>G23),"",1-F23*C23/G23) -> #VALUE! | I23: =IF(H23="","",G23-F23*C23) -> #VALUE! | J23: =IF(OR(I23="",E23="",E23<=0),"",I23*E23) -> #VALUE! | K23: =IF(OR(H23="",C23<=0),"",F23*C23) -> #VALUE! | L23: =IF(A23="","",IF(B23="SKU no encontrado",B23,IF(G23="","Sin precio válido",IF(F23="","Completar precio deseado",IF(OR(F23<0,C23<=0,F23*C23>G23),"Revisar precio deseado",IF(OR(E23="",E23<=0),"Completar bultos","Estimado proporcional"))))))
B24: =IF(A24="","",IF(COUNTIF(Catalogo!$A$5:$A$905,A24)=0,"SKU no encontrado",INDEX(Catalogo!$B$5:$B$905,MATCH(A24,Catalogo!$A$5:$A$905,0)))) | C24: =IF(OR(A24="",B24="SKU no encontrado"),"",INDEX(Catalogo!$C$5:$C$905,MATCH(A24,Catalogo!$A$5:$A$905,0))) | G24: =IF(OR(A24="",B24="SKU no encontrado"),"",IF(INDEX(Catalogo!$H$5:$H$905,MATCH(A24,Catalogo!$A$5:$A$905,0))=0,"",INDEX(Catalogo!$H$5:$H$905,MATCH(A24,Catalogo!$A$5:$A$905,0)))) | H24: =IF(OR(G24="",F24="",F24<0,C24<=0,F24*C24>G24),"",1-F24*C24/G24) -> #VALUE! | I24: =IF(H24="","",G24-F24*C24) -> #VALUE! | J24: =IF(OR(I24="",E24="",E24<=0),"",I24*E24) -> #VALUE! | K24: =IF(OR(H24="",C24<=0),"",F24*C24) -> #VALUE! | L24: =IF(A24="","",IF(B24="SKU no encontrado",B24,IF(G24="","Sin precio válido",IF(F24="","Completar precio deseado",IF(OR(F24<0,C24<=0,F24*C24>G24),"Revisar precio deseado",IF(OR(E24="",E24<=0),"Completar bultos","Estimado proporcional"))))))
B25: =IF(A25="","",IF(COUNTIF(Catalogo!$A$5:$A$905,A25)=0,"SKU no encontrado",INDEX(Catalogo!$B$5:$B$905,MATCH(A25,Catalogo!$A$5:$A$905,0)))) | C25: =IF(OR(A25="",B25="SKU no encontrado"),"",INDEX(Catalogo!$C$5:$C$905,MATCH(A25,Catalogo!$A$5:$A$905,0))) | G25: =IF(OR(A25="",B25="SKU no encontrado"),"",IF(INDEX(Catalogo!$H$5:$H$905,MATCH(A25,Catalogo!$A$5:$A$905,0))=0,"",INDEX(Catalogo!$H$5:$H$905,MATCH(A25,Catalogo!$A$5:$A$905,0)))) | H25: =IF(OR(G25="",F25="",F25<0,C25<=0,F25*C25>G25),"",1-F25*C25/G25) -> #VALUE! | I25: =IF(H25="","",G25-F25*C25) -> #VALUE! | J25: =IF(OR(I25="",E25="",E25<=0),"",I25*E25) -> #VALUE! | K25: =IF(OR(H25="",C25<=0),"",F25*C25) -> #VALUE! | L25: =IF(A25="","",IF(B25="SKU no encontrado",B25,IF(G25="","Sin precio válido",IF(F25="","Completar precio deseado",IF(OR(F25<0,C25<=0,F25*C25>G25),"Revisar precio deseado",IF(OR(E25="",E25<=0),"Completar bultos","Estimado proporcional"))))))
B26: =IF(A26="","",IF(COUNTIF(Catalogo!$A$5:$A$905,A26)=0,"SKU no encontrado",INDEX(Catalogo!$B$5:$B$905,MATCH(A26,Catalogo!$A$5:$A$905,0)))) | C26: =IF(OR(A26="",B26="SKU no encontrado"),"",INDEX(Catalogo!$C$5:$C$905,MATCH(A26,Catalogo!$A$5:$A$905,0))) | G26: =IF(OR(A26="",B26="SKU no encontrado"),"",IF(INDEX(Catalogo!$H$5:$H$905,MATCH(A26,Catalogo!$A$5:$A$905,0))=0,"",INDEX(Catalogo!$H$5:$H$905,MATCH(A26,Catalogo!$A$5:$A$905,0)))) | H26: =IF(OR(G26="",F26="",F26<0,C26<=0,F26*C26>G26),"",1-F26*C26/G26) -> #VALUE! | I26: =IF(H26="","",G26-F26*C26) -> #VALUE! | J26: =IF(OR(I26="",E26="",E26<=0),"",I26*E26) -> #VALUE! | K26: =IF(OR(H26="",C26<=0),"",F26*C26) -> #VALUE! | L26: =IF(A26="","",IF(B26="SKU no encontrado",B26,IF(G26="","Sin precio válido",IF(F26="","Completar precio deseado",IF(OR(F26<0,C26<=0,F26*C26>G26),"Revisar precio deseado",IF(OR(E26="",E26<=0),"Completar bultos","Estimado proporcional"))))))
... B204: =IF(A204="","",IF(COUNTIF(Catalogo!$A$5:$A$905,A204)=0,"SKU no encontrado",INDEX(Catalogo!$B$5:$B$905,MATCH(A204,Catalogo!$A$5:$A$905,0)))) | C204: =IF(OR(A204="",B204="SKU no encontrado"),"",INDEX(Catalogo!$C$5:$C$905,MATCH(A204,Catalogo!$A$5:$A$905,0))) | G204: =IF(OR(A204="",B204="SKU no encontrado"),"",IF(INDEX(Catalogo!$H$5:$H$905,MATCH(A204,Catalogo!$A$5:$A$905,0))=0,"",INDEX(Catalogo!$H$5:$H$905,MATCH(A204,Catalogo!$A$5:$A$905,0)))) | H204: =IF(OR(G204="",F204="",F204<0,C204<=0,F204*C204>G204),"",1-F204*C204/G204) -> #VALUE! | I204: =IF(H204="","",G204-F204*C204) -> #VALUE! | J204: =IF(OR(I204="",E204="",E204<=0),"",I204*E204) -> #VALUE! | K204: =IF(OR(H204="",C204<=0),"",F204*C204) -> #VALUE! | L204: =IF(A204="","",IF(B204="SKU no encontrado",B204,IF(G204="","Sin precio válido",IF(F204="","Completar precio deseado",IF(OR(F204<0,C204<=0,F204*C204>G204),"Revisar precio deseado",IF(OR(E204="",E204<=0),"Completar bultos","Estimado proporcional"))))))
I207: Gasto total cargado | J207: =SUM(J5:J204) -> #VALUE!

Sheet Catalogo
A1: Catálogo de precios
A2: Fuente: plantilla de precios · lista 5. Ceros de origen se conservan y no habilitan una simulación.
A4: SKU | B4: Descripción | C4: Unidades por bulto | D4: Bultos por pallet | E4: Lista | F4: Precio Base / bulto | G4: P. Final / bulto | H4: Final calculado / bulto | I4: Final calculado / unidad | J4: Evidencia
A5: 544 | B5: CHAPADUR (SUR) | C5: 1 | D5: 200 | E5: 5 | F5: 6615.65 | G5: 8004.937 | H5: =IF(OR(F5<=0,G5<=0),"",ROUND(G5+F5*Uso!$B$5,Uso!$B$6)) -> 8203.407 | I5: =IF(OR(H5="",C5<=0),"",H5/C5) -> 8203.407 | J5: =IF(COUNTIF(Cruce!$A$5:$A$14,A5)>0,"SKU de muestra","Regla extrapolada") -> Regla extrapolada
A6: 591 | B6: MIRINDA MANZANA * X8 PET2250 | C6: 8 | D6: 60 | E6: 5 | F6: 14738.66 | G6: 18606.279 | H6: =IF(OR(F6<=0,G6<=0),"",ROUND(G6+F6*Uso!$B$5,Uso!$B$6)) -> 19048.439 | I6: =IF(OR(H6="",C6<=0),"",H6/C6) -> 2381.0549 | J6: =IF(COUNTIF(Cruce!$A$5:$A$14,A6)>0,"SKU de muestra","Regla extrapolada") -> SKU de muestra
A7: 627 | B7: MIRINDA NARANJA * X8 PET2250 | C7: 8 | D7: 60 | E7: 5 | F7: 14738.66 | G7: 18606.279 | H7: =IF(OR(F7<=0,G7<=0),"",ROUND(G7+F7*Uso!$B$5,Uso!$B$6)) -> 19048.439 | I7: =IF(OR(H7="",C7<=0),"",H7/C7) -> 2381.0549 | J7: =IF(COUNTIF(Cruce!$A$5:$A$14,A7)>0,"SKU de muestra","Regla extrapolada") -> Regla extrapolada
A8: 1321 | B8: PALETA NO CHEP | C8: 1 | D8: 1 | E8: 5 | F8: 29950.72 | G8: 36240.371 | H8: =IF(OR(F8<=0,G8<=0),"",ROUND(G8+F8*Uso!$B$5,Uso!$B$6)) -> 37138.893 | I8: =IF(OR(H8="",C8<=0),"",H8/C8) -> 37138.893 | J8: =IF(COUNTIF(Cruce!$A$5:$A$14,A8)>0,"SKU de muestra","Regla extrapolada") -> Regla extrapolada
A9: 1413 | B9: GATORADE NARANJA * X6 PET 500 | C9: 6 | D9: 315 | E9: 5 | F9: 10154.15 | G9: 12286.522 | H9: =IF(OR(F9<=0,G9<=0),"",ROUND(G9+F9*Uso!$B$5,Uso!$B$6)) -> 12591.147 | I9: =IF(OR(H9="",C9<=0),"",H9/C9) -> 2098.5245 | J9: =IF(COUNTIF(Cruce!$A$5:$A$14,A9)>0,"SKU de muestra","Regla extrapolada") -> Regla extrapolada
A10: 1416 | B10: GATORADE MANZANA * X6 PET 500 | C10: 6 | D10: 315 | E10: 5 | F10: 10154.15 | G10: 12286.522 | H10: =IF(OR(F10<=0,G10<=0),"",ROUND(G10+F10*Uso!$B$5,Uso!$B$6)) -> 12591.147 | I10: =IF(OR(H10="",C10<=0),"",H10/C10) -> 2098.5245 | J10: =IF(COUNTIF(Cruce!$A$5:$A$14,A10)>0,"SKU de muestra","Regla extrapolada") -> SKU de muestra
A11: 1418 | B11: GATORADE COOLBLU * X6 PET 500 | C11: 6 | D11: 315 | E11: 5 | F11: 10154.15 | G11: 12286.522 | H11: =IF(OR(F11<=0,G11<=0),"",ROUND(G11+F11*Uso!$B$5,Uso!$B$6)) -> 12591.147 | I11: =IF(OR(H11="",C11<=0),"",H11/C11) -> 2098.5245 | J11: =IF(COUNTIF(Cruce!$A$5:$A$14,A11)>0,"SKU de muestra","Regla extrapolada") -> Regla extrapolada
A12: 1422 | B12: GATORADE UVA * X6 PET 500 | C12: 6 | D12: 315 | E12: 5 | F12: 10154.15 | G12: 12286.522 | H12: =IF(OR(F12<=0,G12<=0),"",ROUND(G12+F12*Uso!$B$5,Uso!$B$6)) -> 12591.147 | I12: =IF(OR(H12="",C12<=0),"",H12/C12) -> 2098.5245 | J12: =IF(COUNTIF(Cruce!$A$5:$A$14,A12)>0,"SKU de muestra","Regla extrapolada") -> Regla extrapolada
A13: 1659 | B13: H2OH CITRUS X8 PET2250 | C13: 8 | D13: 60 | E13: 5 | F13: 22063.34 | G13: 26696.641 | H13: =IF(OR(F13<=0,G13<=0),"",ROUND(G13+F13*Uso!$B$5,Uso!$B$6)) -> 27358.541 | I13: =IF(OR(H13="",C13<=0),"",H13/C13) -> 3419.8176 | J13: =IF(COUNTIF(Cruce!$A$5:$A$14,A13)>0,"SKU de muestra","Regla extrapolada") -> Regla extrapolada
A14: 1808 | B14: FRAPERA ANDES REFERENTE | C14: 1 | D14: 1 | E14: 0 | F14: 0 | G14: 0 | H14: =IF(OR(F14<=0,G14<=0),"",ROUND(G14+F14*Uso!$B$5,Uso!$B$6)) | I14: =IF(OR(H14="",C14<=0),"",H14/C14) | J14: =IF(COUNTIF(Cruce!$A$5:$A$14,A14)>0,"SKU de muestra","Regla extrapolada") -> Regla extrapolada
A15: 2152 | B15: BOT 1/2 ECO 20 | C15: 20 | D15: 70 | E15: 0 | F15: 0 | G15: 0 | H15: =IF(OR(F15<=0,G15<=0),"",ROUND(G15+F15*Uso!$B$5,Uso!$B$6)) | I15: =IF(OR(H15="",C15<=0),"",H15/C15) | J15: =IF(COUNTIF(Cruce!$A$5:$A$14,A15)>0,"SKU de muestra","Regla extrapolada") -> Regla extrapolada
A16: 2153 | B16: Q ECO X 20 | C16: 1 | D16: 70 | E16: 0 | F16: 0 | G16: 0 | H16: =IF(OR(F16<=0,G16<=0),"",ROUND(G16+F16*Uso!$B$5,Uso!$B$6)) | I16: =IF(OR(H16="",C16<=0),"",H16/C16) | J16: =IF(COUNTIF(Cruce!$A$5:$A$14,A16)>0,"SKU de muestra","Regla extrapolada") -> Regla extrapolada
... A904: 900437 | B904: COMBO MAY GASEOSAS FAM - PATAGONIA SUR | C904: 1 | D904: 0 | E904: 5 | F904: 909965.56 | G904: 1148760.3 | H904: =IF(OR(F904<=0,G904<=0),"",ROUND(G904+F904*Uso!$B$5,Uso!$B$6)) -> 1176059.3 | I904: =IF(OR(H904="",C904<=0),"",H904/C904) -> 1176059.3 | J904: =IF(COUNTIF(Cruce!$A$5:$A$14,A904)>0,"SKU de muestra","Regla extrapolada") -> Regla extrapolada
A905: null | H905: =IF(OR(F905<=0,G905<=0),"",ROUND(G905+F905*Uso!$B$5,Uso!$B$6)) | I905: =IF(OR(H905="",C905<=0),"",H905/C905) | J905: =IF(COUNTIF(Cruce!$A$5:$A$14,A905)>0,"SKU de muestra","Regla extrapolada") -> Regla extrapolada

Sheet Cruce
A1: Comparación de los 10 SKU
A2: Diferencias calculadas con los datos originales. El recargo observado se mide sobre Precio Base.
A4: SKU | B4: Descripción | C4: Base exportación | D4: Final exportación | E4: Base lista | F4: Final lista | G4: Diferencia $ | H4: Recargo / base | I4: Final con regla | J4: Diferencia residual
A5: 2218 | B5: QUILMES - 4X6 LAT 473 | C5: 35556.58 | D5: 48405.919 | E5: =INDEX(Catalogo!$F$5:$F$905,MATCH(A5,Catalogo!$A$5:$A$905,0)) -> 35556.58 | F5: =INDEX(Catalogo!$G$5:$G$905,MATCH(A5,Catalogo!$A$5:$A$905,0)) -> 47339.222 | G5: =D5-F5 -> 1066.697 | H5: =G5/C5 -> 0.029999989 | I5: =ROUND(F5+E5*Uso!$B$5,Uso!$B$6) -> 48405.919 | J5: =D5-I5 -> 0
A6: 19253 | B6: ANDES ORIGEN IPA RET X12 1000 | C6: 37779.4 | D6: 50984.146 | E6: =INDEX(Catalogo!$F$5:$F$905,MATCH(A6,Catalogo!$A$5:$A$905,0)) -> 37779.4 | F6: =INDEX(Catalogo!$G$5:$G$905,MATCH(A6,Catalogo!$A$5:$A$905,0)) -> 49850.764 | G6: =D6-F6 -> 1133.382 | H6: =G6/C6 -> 0.03 | I6: =ROUND(F6+E6*Uso!$B$5,Uso!$B$6) -> 50984.146 | J6: =D6-I6 -> 0
A7: 30645 | B7: PEPSI 70KCAL PET X8 2000CC | C7: 22815.92 | D7: 29656.171 | E7: =INDEX(Catalogo!$F$5:$F$905,MATCH(A7,Catalogo!$A$5:$A$905,0)) -> 22815.92 | F7: =INDEX(Catalogo!$G$5:$G$905,MATCH(A7,Catalogo!$A$5:$A$905,0)) -> 28971.693 | G7: =D7-F7 -> 684.478 | H7: =G7/C7 -> 0.030000018 | I7: =ROUND(F7+E7*Uso!$B$5,Uso!$B$6) -> 29656.171 | J7: =D7-I7 -> 0
A8: 49807 | B8: STELLA PURE GOLD CAN 4X6 473CC T | C8: 52770.17 | D8: 72010.181 | E8: =INDEX(Catalogo!$F$5:$F$905,MATCH(A8,Catalogo!$A$5:$A$905,0)) -> 52770.17 | F8: =INDEX(Catalogo!$G$5:$G$905,MATCH(A8,Catalogo!$A$5:$A$905,0)) -> 70427.076 | G8: =D8-F8 -> 1583.105 | H8: =G8/C8 -> 0.029999998 | I8: =ROUND(F8+E8*Uso!$B$5,Uso!$B$6) -> 72010.181 | J8: =D8-I8 -> 0
A9: 24931 | B9: STELLA ART NOIRE PM CAN 4X6 473CC CART | C9: 52770.17 | D9: 72010.181 | E9: =INDEX(Catalogo!$F$5:$F$905,MATCH(A9,Catalogo!$A$5:$A$905,0)) -> 52770.17 | F9: =INDEX(Catalogo!$G$5:$G$905,MATCH(A9,Catalogo!$A$5:$A$905,0)) -> 70427.076 | G9: =D9-F9 -> 1583.105 | H9: =G9/C9 -> 0.029999998 | I9: =ROUND(F9+E9*Uso!$B$5,Uso!$B$6) -> 72010.181 | J9: =D9-I9 -> 0
A10: 31434 | B10: BRAHMA CAN 4X4 710CC | C10: 32764.35 | D10: 44562.414 | E10: =INDEX(Catalogo!$F$5:$F$905,MATCH(A10,Catalogo!$A$5:$A$905,0)) -> 32764.35 | F10: =INDEX(Catalogo!$G$5:$G$905,MATCH(A10,Catalogo!$A$5:$A$905,0)) -> 43579.484 | G10: =D10-F10 -> 982.93 | H10: =G10/C10 -> 0.029999985 | I10: =ROUND(F10+E10*Uso!$B$5,Uso!$B$6) -> 44562.415 | J10: =D10-I10 -> -0.001
A11: 591 | B11: MIRINDA MANZANA * X8 PET2250 | C11: 14738.66 | D11: 19048.438 | E11: =INDEX(Catalogo!$F$5:$F$905,MATCH(A11,Catalogo!$A$5:$A$905,0)) -> 14738.66 | F11: =INDEX(Catalogo!$G$5:$G$905,MATCH(A11,Catalogo!$A$5:$A$905,0)) -> 18606.279 | G11: =D11-F11 -> 442.159 | H11: =G11/C11 -> 0.029999946 | I11: =ROUND(F11+E11*Uso!$B$5,Uso!$B$6) -> 19048.439 | J11: =D11-I11 -> -0.001
A12: 16371 | B12: RED BULL CAN 6X4 250 | C12: 53107.46 | D12: 65853.25 | E12: =INDEX(Catalogo!$F$5:$F$905,MATCH(A12,Catalogo!$A$5:$A$905,0)) -> 53107.46 | F12: =INDEX(Catalogo!$G$5:$G$905,MATCH(A12,Catalogo!$A$5:$A$905,0)) -> 64260.027 | G12: =D12-F12 -> 1593.223 | H12: =G12/C12 -> 0.029999985 | I12: =ROUND(F12+E12*Uso!$B$5,Uso!$B$6) -> 65853.251 | J12: =D12-I12 -> -0.001
A13: 22185 | B13: GLACIAR SG PET X6 750 222 PC | C13: 7887.72 | D13: 10016.943 | E13: =INDEX(Catalogo!$F$5:$F$905,MATCH(A13,Catalogo!$A$5:$A$905,0)) -> 7887.72 | F13: =INDEX(Catalogo!$G$5:$G$905,MATCH(A13,Catalogo!$A$5:$A$905,0)) -> 9780.311 | G13: =D13-F13 -> 236.632 | H13: =G13/C13 -> 0.030000051 | I13: =ROUND(F13+E13*Uso!$B$5,Uso!$B$6) -> 10016.943 | J13: =D13-I13 -> 0
A14: 1416 | B14: GATORADE MANZANA * X6 PET 500 | C14: 10154.15 | D14: 12591.146 | E14: =INDEX(Catalogo!$F$5:$F$905,MATCH(A14,Catalogo!$A$5:$A$905,0)) -> 10154.15 | F14: =INDEX(Catalogo!$G$5:$G$905,MATCH(A14,Catalogo!$A$5:$A$905,0)) -> 12286.522 | G14: =D14-F14 -> 304.624 | H14: =G14/C14 -> 0.029999951 | I14: =ROUND(F14+E14*Uso!$B$5,Uso!$B$6) -> 12591.147 | J14: =D14-I14 -> -0.001

Sheet Trelew
A1: Frescura Trelew: precio por unidad
A2: Ingresar precio unitario en F. Bultos en E precargados con stock del lote; ajustar si se bonifica una parte.
A4: SKU | B4: Descripción | C4: Unidades por bulto | D4: Vencimiento | E4: Bultos a descontar | F4: Final deseado / unidad sugerido | G4: Final deseado / unidad2 | H4: Final actual / bulto | I4: Descuento requerido | J4: Importe cedido / bulto | K4: Gasto total descuento | L4: Final deseado / bulto | M4: Estado | N4: Estado frescura de origen | O4: Stock lote / bultos | P4: Orden lote en origen | Q4: Días p/ bloqueo de origen | R4: Final actual / unidad
A5: 30793 | B5: =IF(A5="","",IF(COUNTIF(Catalogo!$A$5:$A$905,A5)=0,"SKU no encontrado",INDEX(Catalogo!$B$5:$B$905,MATCH(A5,Catalogo!$A$5:$A$905,0)))) -> PEPSI BLACK CAN 4X6 354CC 2024 | C5: =IF(OR(A5="",B5="SKU no encontrado"),"",INDEX(Catalogo!$C$5:$C$905,MATCH(A5,Catalogo!$A$5:$A$905,0))) -> 24 | D5: 46302 | E5: 87.583333 | F5: 1000 | G5: =+LotesTrelew[[#This Row],[Final deseado / unidad sugerido]]/1.3 -> 769.23077 | H5: =IF(OR(A5="",B5="SKU no encontrado"),"",IF(INDEX(Catalogo!$H$5:$H$905,MATCH(A5,Catalogo!$A$5:$A$905,0))=0,"",INDEX(Catalogo!$H$5:$H$905,MATCH(A5,Catalogo!$A$5:$A$905,0)))) -> 38965.599 | I5: =IF(OR(N5="ELIMINAR",H5="",G5="",G5<0,C5<=0,G5*C5>H5,E5>O5),"",1-G5*C5/H5) -> 0.5262093 | J5: =IF(I5="","",H5-G5*C5) -> 20504.061 | K5: =IF(OR(J5="",E5="",E5<=0),"",J5*E5) -> 1795814 | L5: =IF(OR(I5="",C5<=0),"",G5*C5) -> 18461.538 | M5: =IF(N5="ELIMINAR","ELIMINAR según origen",IF(H5="","Sin precio válido",IF(C5<=0,"Sin unidades por bulto",IF(G5="","Completar precio unitario",IF(OR(G5<0,G5*C5>H5),"Revisar precio unitario",IF(OR(E5<=0,E5>O5),"Revisar bultos vs. stock","Estimado proporcional")))))) -> Estimado proporcional | N5: ACCIONAR | O5: 87.583333 | P5: 1 | Q5: 17 | R5: =IF(OR(H5="",C5<=0),"",H5/C5) -> 1623.5666
A6: 32642 | B6: =IF(A6="","",IF(COUNTIF(Catalogo!$A$5:$A$905,A6)=0,"SKU no encontrado",INDEX(Catalogo!$B$5:$B$905,MATCH(A6,Catalogo!$A$5:$A$905,0)))) -> PATAGONIA IPA OW X6 730CC TERMO | C6: =IF(OR(A6="",B6="SKU no encontrado"),"",INDEX(Catalogo!$C$5:$C$905,MATCH(A6,Catalogo!$A$5:$A$905,0))) -> 6 | D6: 46305 | E6: 735 | G6: =+LotesTrelew[[#This Row],[Final deseado / unidad sugerido]]/1.3 -> 0 | H6: =IF(OR(A6="",B6="SKU no encontrado"),"",IF(INDEX(Catalogo!$H$5:$H$905,MATCH(A6,Catalogo!$A$5:$A$905,0))=0,"",INDEX(Catalogo!$H$5:$H$905,MATCH(A6,Catalogo!$A$5:$A$905,0)))) -> 29135.981 | I6: =IF(OR(N6="ELIMINAR",H6="",G6="",G6<0,C6<=0,G6*C6>H6,E6>O6),"",1-G6*C6/H6) -> 1 | J6: =IF(I6="","",H6-G6*C6) -> 29135.981 | K6: =IF(OR(J6="",E6="",E6<=0),"",J6*E6) -> 21414946 | L6: =IF(OR(I6="",C6<=0),"",G6*C6) -> 0 | M6: =IF(N6="ELIMINAR","ELIMINAR según origen",IF(H6="","Sin precio válido",IF(C6<=0,"Sin unidades por bulto",IF(G6="","Completar precio unitario",IF(OR(G6<0,G6*C6>H6),"Revisar precio unitario",IF(OR(E6<=0,E6>O6),"Revisar bultos vs. stock","Estimado proporcional")))))) -> Estimado proporcional | N6: ACCIONAR | O6: 735 | P6: 1 | Q6: 20 | R6: =IF(OR(H6="",C6<=0),"",H6/C6) -> 4855.9968
A7: 44489 | B7: =IF(A7="","",IF(COUNTIF(Catalogo!$A$5:$A$905,A7)=0,"SKU no encontrado",INDEX(Catalogo!$B$5:$B$905,MATCH(A7,Catalogo!$A$5:$A$905,0)))) -> STELLA ARTOIS 0.0 SY CAN 4X6 473CC CART | C7: =IF(OR(A7="",B7="SKU no encontrado"),"",INDEX(Catalogo!$C$5:$C$905,MATCH(A7,Catalogo!$A$5:$A$905,0))) -> 24 | D7: 46307 | E7: 177.75 | G7: =+LotesTrelew[[#This Row],[Final deseado / unidad sugerido]]/1.3 -> 0 | H7: =IF(OR(A7="",B7="SKU no encontrado"),"",IF(INDEX(Catalogo!$H$5:$H$905,MATCH(A7,Catalogo!$A$5:$A$905,0))=0,"",INDEX(Catalogo!$H$5:$H$905,MATCH(A7,Catalogo!$A$5:$A$905,0)))) -> 55342.279 | I7: =IF(OR(N7="ELIMINAR",H7="",G7="",G7<0,C7<=0,G7*C7>H7,E7>O7),"",1-G7*C7/H7) -> 1 | J7: =IF(I7="","",H7-G7*C7) -> 55342.279 | K7: =IF(OR(J7="",E7="",E7<=0),"",J7*E7) -> 9837090.1 | L7: =IF(OR(I7="",C7<=0),"",G7*C7) -> 0 | M7: =IF(N7="ELIMINAR","ELIMINAR según origen",IF(H7="","Sin precio válido",IF(C7<=0,"Sin unidades por bulto",IF(G7="","Completar precio unitario",IF(OR(G7<0,G7*C7>H7),"Revisar precio unitario",IF(OR(E7<=0,E7>O7),"Revisar bultos vs. stock","Estimado proporcional")))))) -> Estimado proporcional | N7: ACCIONAR | O7: 177.75 | P7: 1 | Q7: 22 | R7: =IF(OR(H7="",C7<=0),"",H7/C7) -> 2305.9283
A8: 8067 | B8: =IF(A8="","",IF(COUNTIF(Catalogo!$A$5:$A$905,A8)=0,"SKU no encontrado",INDEX(Catalogo!$B$5:$B$905,MATCH(A8,Catalogo!$A$5:$A$905,0)))) -> H2OH LIMONETO X8 PET2250 | C8: =IF(OR(A8="",B8="SKU no encontrado"),"",INDEX(Catalogo!$C$5:$C$905,MATCH(A8,Catalogo!$A$5:$A$905,0))) -> 8 | D8: 46309 | E8: 32.875 | G8: =+LotesTrelew[[#This Row],[Final deseado / unidad sugerido]]/1.3 -> 0 | H8: =IF(OR(A8="",B8="SKU no encontrado"),"",IF(INDEX(Catalogo!$H$5:$H$905,MATCH(A8,Catalogo!$A$5:$A$905,0))=0,"",INDEX(Catalogo!$H$5:$H$905,MATCH(A8,Catalogo!$A$5:$A$905,0)))) -> 27358.541 | I8: =IF(OR(N8="ELIMINAR",H8="",G8="",G8<0,C8<=0,G8*C8>H8,E8>O8),"",1-G8*C8/H8) -> 1 | J8: =IF(I8="","",H8-G8*C8) -> 27358.541 | K8: =IF(OR(J8="",E8="",E8<=0),"",J8*E8) -> 899412.04 | L8: =IF(OR(I8="",C8<=0),"",G8*C8) -> 0 | M8: =IF(N8="ELIMINAR","ELIMINAR según origen",IF(H8="","Sin precio válido",IF(C8<=0,"Sin unidades por bulto",IF(G8="","Completar precio unitario",IF(OR(G8<0,G8*C8>H8),"Revisar precio unitario",IF(OR(E8<=0,E8>O8),"Revisar bultos vs. stock","Estimado proporcional")))))) -> Estimado proporcional | N8: ACCIONAR | O8: 32.875 | P8: 1 | Q8: 24 | R8: =IF(OR(H8="",C8<=0),"",H8/C8) -> 3419.8176
A9: 31601 | B9: =IF(A9="","",IF(COUNTIF(Catalogo!$A$5:$A$905,A9)=0,"SKU no encontrado",INDEX(Catalogo!$B$5:$B$905,MATCH(A9,Catalogo!$A$5:$A$905,0)))) -> H2OH STILL LIMON PET X8 2000CC | C9: =IF(OR(A9="",B9="SKU no encontrado"),"",INDEX(Catalogo!$C$5:$C$905,MATCH(A9,Catalogo!$A$5:$A$905,0))) -> 8 | D9: 46310 | E9: 48 | G9: =+LotesTrelew[[#This Row],[Final deseado / unidad sugerido]]/1.3 -> 0 | H9: =IF(OR(A9="",B9="SKU no encontrado"),"",IF(INDEX(Catalogo!$H$5:$H$905,MATCH(A9,Catalogo!$A$5:$A$905,0))=0,"",INDEX(Catalogo!$H$5:$H$905,MATCH(A9,Catalogo!$A$5:$A$905,0)))) -> 27312.145 | I9: =IF(OR(N9="ELIMINAR",H9="",G9="",G9<0,C9<=0,G9*C9>H9,E9>O9),"",1-G9*C9/H9) -> 1 | J9: =IF(I9="","",H9-G9*C9) -> 27312.145 | K9: =IF(OR(J9="",E9="",E9<=0),"",J9*E9) -> 1310983 | L9: =IF(OR(I9="",C9<=0),"",G9*C9) -> 0 | M9: =IF(N9="ELIMINAR","ELIMINAR según origen",IF(H9="","Sin precio válido",IF(C9<=0,"Sin unidades por bulto",IF(G9="","Completar precio unitario",IF(OR(G9<0,G9*C9>H9),"Revisar precio unitario",IF(OR(E9<=0,E9>O9),"Revisar bultos vs. stock","Estimado proporcional")))))) -> Estimado proporcional | N9: ACCIONAR | O9: 48 | P9: 1 | Q9: 25 | R9: =IF(OR(H9="",C9<=0),"",H9/C9) -> 3414.0181
A10: 31206 | B10: =IF(A10="","",IF(COUNTIF(Catalogo!$A$5:$A$905,A10)=0,"SKU no encontrado",INDEX(Catalogo!$B$5:$B$905,MATCH(A10,Catalogo!$A$5:$A$905,0)))) -> ANDES ORIGEN RUBIA 2.0 CAN 4X4 710CC | C10: =IF(OR(A10="",B10="SKU no encontrado"),"",INDEX(Catalogo!$C$5:$C$905,MATCH(A10,Catalogo!$A$5:$A$905,0))) -> 16 | D10: 46320 | E10: 401.8125 | G10: =+LotesTrelew[[#This Row],[Final deseado / unidad sugerido]]/1.3 -> 0 | H10: =IF(OR(A10="",B10="SKU no encontrado"),"",IF(INDEX(Catalogo!$H$5:$H$905,MATCH(A10,Catalogo!$A$5:$A$905,0))=0,"",INDEX(Catalogo!$H$5:$H$905,MATCH(A10,Catalogo!$A$5:$A$905,0)))) -> 54426.143 | I10: =IF(OR(N10="ELIMINAR",H10="",G10="",G10<0,C10<=0,G10*C10>H10,E10>O10),"",1-G10*C10/H10) -> 1 | J10: =IF(I10="","",H10-G10*C10) -> 54426.143 | K10: =IF(OR(J10="",E10="",E10<=0),"",J10*E10) -> 21869105 | L10: =IF(OR(I10="",C10<=0),"",G10*C10) -> 0 | M10: =IF(N10="ELIMINAR","ELIMINAR según origen",IF(H10="","Sin precio válido",IF(C10<=0,"Sin unidades por bulto",IF(G10="","Completar precio unitario",IF(OR(G10<0,G10*C10>H10),"Revisar precio unitario",IF(OR(E10<=0,E10>O10),"Revisar bultos vs. stock","Estimado proporcional")))))) -> Estimado proporcional | N10: ACCIONAR | O10: 401.8125 | P10: 1 | Q10: 35 | R10: =IF(OR(H10="",C10<=0),"",H10/C10) -> 3401.6339
A11: 24118 | B11: =IF(A11="","",IF(COUNTIF(Catalogo!$A$5:$A$905,A11)=0,"SKU no encontrado",INDEX(Catalogo!$B$5:$B$905,MATCH(A11,Catalogo!$A$5:$A$905,0)))) -> ROCKSTAR OW BOT X6 500CC | C11: =IF(OR(A11="",B11="SKU no encontrado"),"",INDEX(Catalogo!$C$5:$C$905,MATCH(A11,Catalogo!$A$5:$A$905,0))) -> 6 | D11: 46326 | E11: 386 | G11: =+LotesTrelew[[#This Row],[Final deseado / unidad sugerido]]/1.3 -> 0 | H11: =IF(OR(A11="",B11="SKU no encontrado"),"",IF(INDEX(Catalogo!$H$5:$H$905,MATCH(A11,Catalogo!$A$5:$A$905,0))=0,"",INDEX(Catalogo!$H$5:$H$905,MATCH(A11,Catalogo!$A$5:$A$905,0)))) -> 10235.629 | I11: =IF(OR(N11="ELIMINAR",H11="",G11="",G11<0,C11<=0,G11*C11>H11,E11>O11),"",1-G11*C11/H11) -> 1 | J11: =IF(I11="","",H11-G11*C11) -> 10235.629 | K11: =IF(OR(J11="",E11="",E11<=0),"",J11*E11) -> 3950952.8 | L11: =IF(OR(I11="",C11<=0),"",G11*C11) -> 0 | M11: =IF(N11="ELIMINAR","ELIMINAR según origen",IF(H11="","Sin precio válido",IF(C11<=0,"Sin unidades por bulto",IF(G11="","Completar precio unitario",IF(OR(G11<0,G11*C11>H11),"Revisar precio unitario",IF(OR(E11<=0,E11>O11),"Revisar bultos vs. stock","Estimado proporcional")))))) -> Estimado proporcional | N11: ACCIONAR | O11: 386 | P11: 1 | Q11: 41 | R11: =IF(OR(H11="",C11<=0),"",H11/C11) -> 1705.9382
A12: 29649 | B12: =IF(A12="","",IF(COUNTIF(Catalogo!$A$5:$A$905,A12)=0,"SKU no encontrado",INDEX(Catalogo!$B$5:$B$905,MATCH(A12,Catalogo!$A$5:$A$905,0)))) -> STELLA ARTOIS CAN 4X4 710CC | C12: =IF(OR(A12="",B12="SKU no encontrado"),"",INDEX(Catalogo!$C$5:$C$905,MATCH(A12,Catalogo!$A$5:$A$905,0))) -> 16 | D12: 46328 | E12: 270 | G12: =+LotesTrelew[[#This Row],[Final deseado / unidad sugerido]]/1.3 -> 0 | H12: =IF(OR(A12="",B12="SKU no encontrado"),"",IF(INDEX(Catalogo!$H$5:$H$905,MATCH(A12,Catalogo!$A$5:$A$905,0))=0,"",INDEX(Catalogo!$H$5:$H$905,MATCH(A12,Catalogo!$A$5:$A$905,0)))) -> 70533.793 | I12: =IF(OR(N12="ELIMINAR",H12="",G12="",G12<0,C12<=0,G12*C12>H12,E12>O12),"",1-G12*C12/H12) -> 1 | J12: =IF(I12="","",H12-G12*C12) -> 70533.793 | K12: =IF(OR(J12="",E12="",E12<=0),"",J12*E12) -> 19044124 | L12: =IF(OR(I12="",C12<=0),"",G12*C12) -> 0 | M12: =IF(N12="ELIMINAR","ELIMINAR según origen",IF(H12="","Sin precio válido",IF(C12<=0,"Sin unidades por bulto",IF(G12="","Completar precio unitario",IF(OR(G12<0,G12*C12>H12),"Revisar precio unitario",IF(OR(E12<=0,E12>O12),"Revisar bultos vs. stock","Estimado proporcional")))))) -> Estimado proporcional | N12: ACCIONAR | O12: 270 | P12: 2 | Q12: 43 | R12: =IF(OR(H12="",C12<=0),"",H12/C12) -> 4408.3621
A13: 31074 | B13: =IF(A13="","",IF(COUNTIF(Catalogo!$A$5:$A$905,A13)=0,"SKU no encontrado",INDEX(Catalogo!$B$5:$B$905,MATCH(A13,Catalogo!$A$5:$A$905,0)))) -> PDT POMELO CAN 4X6 269CC 169 BULTOS | C13: =IF(OR(A13="",B13="SKU no encontrado"),"",INDEX(Catalogo!$C$5:$C$905,MATCH(A13,Catalogo!$A$5:$A$905,0))) -> 24 | D13: 46328 | E13: 236.33333 | G13: =+LotesTrelew[[#This Row],[Final deseado / unidad sugerido]]/1.3 -> 0 | H13: =IF(OR(A13="",B13="SKU no encontrado"),"",IF(INDEX(Catalogo!$H$5:$H$905,MATCH(A13,Catalogo!$A$5:$A$905,0))=0,"",INDEX(Catalogo!$H$5:$H$905,MATCH(A13,Catalogo!$A$5:$A$905,0)))) -> 23665.952 | I13: =IF(OR(N13="ELIMINAR",H13="",G13="",G13<0,C13<=0,G13*C13>H13,E13>O13),"",1-G13*C13/H13) -> 1 | J13: =IF(I13="","",H13-G13*C13) -> 23665.952 | K13: =IF(OR(J13="",E13="",E13<=0),"",J13*E13) -> 5593053.3 | L13: =IF(OR(I13="",C13<=0),"",G13*C13) -> 0 | M13: =IF(N13="ELIMINAR","ELIMINAR según origen",IF(H13="","Sin precio válido",IF(C13<=0,"Sin unidades por bulto",IF(G13="","Completar precio unitario",IF(OR(G13<0,G13*C13>H13),"Revisar precio unitario",IF(OR(E13<=0,E13>O13),"Revisar bultos vs. stock","Estimado proporcional")))))) -> Estimado proporcional | N13: ACCIONAR | O13: 236.33333 | P13: 1 | Q13: 43 | R13: =IF(OR(H13="",C13<=0),"",H13/C13) -> 986.08133
A14: 28698 | B14: =IF(A14="","",IF(COUNTIF(Catalogo!$A$5:$A$905,A14)=0,"SKU no encontrado",INDEX(Catalogo!$B$5:$B$905,MATCH(A14,Catalogo!$A$5:$A$905,0)))) -> STELLA ARTOIS 0.0% OW 4X6 330CC | C14: =IF(OR(A14="",B14="SKU no encontrado"),"",INDEX(Catalogo!$C$5:$C$905,MATCH(A14,Catalogo!$A$5:$A$905,0))) -> 24 | D14: 46330 | E14: 80.5 | G14: =+LotesTrelew[[#This Row],[Final deseado / unidad sugerido]]/1.3 -> 0 | H14: =IF(OR(A14="",B14="SKU no encontrado"),"",IF(INDEX(Catalogo!$H$5:$H$905,MATCH(A14,Catalogo!$A$5:$A$905,0))=0,"",INDEX(Catalogo!$H$5:$H$905,MATCH(A14,Catalogo!$A$5:$A$905,0)))) -> 55342.279 | I14: =IF(OR(N14="ELIMINAR",H14="",G14="",G14<0,C14<=0,G14*C14>H14,E14>O14),"",1-G14*C14/H14) -> 1 | J14: =IF(I14="","",H14-G14*C14) -> 55342.279 | K14: =IF(OR(J14="",E14="",E14<=0),"",J14*E14) -> 4455053.5 | L14: =IF(OR(I14="",C14<=0),"",G14*C14) -> 0 | M14: =IF(N14="ELIMINAR","ELIMINAR según origen",IF(H14="","Sin precio válido",IF(C14<=0,"Sin unidades por bulto",IF(G14="","Completar precio unitario",IF(OR(G14<0,G14*C14>H14),"Revisar precio unitario",IF(OR(E14<=0,E14>O14),"Revisar bultos vs. stock","Estimado proporcional")))))) -> Estimado proporcional | N14: ACCIONAR | O14: 80.5 | P14: 1 | Q14: 45 | R14: =IF(OR(H14="",C14<=0),"",H14/C14) -> 2305.9283
A15: 16225 | B15: =IF(A15="","",IF(COUNTIF(Catalogo!$A$5:$A$905,A15)=0,"SKU no encontrado",INDEX(Catalogo!$B$5:$B$905,MATCH(A15,Catalogo!$A$5:$A$905,0)))) -> PATAGONIA AMBER CAN 4X6 473 CART | C15: =IF(OR(A15="",B15="SKU no encontrado"),"",INDEX(Catalogo!$C$5:$C$905,MATCH(A15,Catalogo!$A$5:$A$905,0))) -> 24 | D15: 46348 | E15: 116.25 | G15: =+LotesTrelew[[#This Row],[Final deseado / unidad sugerido]]/1.3 -> 0 | H15: =IF(OR(A15="",B15="SKU no encontrado"),"",IF(INDEX(Catalogo!$H$5:$H$905,MATCH(A15,Catalogo!$A$5:$A$905,0))=0,"",INDEX(Catalogo!$H$5:$H$905,MATCH(A15,Catalogo!$A$5:$A$905,0)))) -> 79485.894 | I15: =IF(OR(N15="ELIMINAR",H15="",G15="",G15<0,C15<=0,G15*C15>H15,E15>O15),"",1-G15*C15/H15) -> 1 | J15: =IF(I15="","",H15-G15*C15) -> 79485.894 | K15: =IF(OR(J15="",E15="",E15<=0),"",J15*E15) -> 9240235.2 | L15: =IF(OR(I15="",C15<=0),"",G15*C15) -> 0 | M15: =IF(N15="ELIMINAR","ELIMINAR según origen",IF(H15="","Sin precio válido",IF(C15<=0,"Sin unidades por bulto",IF(G15="","Completar precio unitario",IF(OR(G15<0,G15*C15>H15),"Revisar precio unitario",IF(OR(E15<=0,E15>O15),"Revisar bultos vs. stock","Estimado proporcional")))))) -> Estimado proporcional | N15: ACCIONAR | O15: 116.25 | P15: 1 | Q15: 63 | R15: =IF(OR(H15="",C15<=0),"",H15/C15) -> 3311.9122
A16: 32489 | B16: =IF(A16="","",IF(COUNTIF(Catalogo!$A$5:$A$905,A16)=0,"SKU no encontrado",INDEX(Catalogo!$B$5:$B$905,MATCH(A16,Catalogo!$A$5:$A$905,0)))) -> H2OH S/GAS NARANJA PET X6 500CC | C16: =IF(OR(A16="",B16="SKU no encontrado"),"",INDEX(Catalogo!$C$5:$C$905,MATCH(A16,Catalogo!$A$5:$A$905,0))) -> 6 | D16: 46356 | E16: 255 | G16: =+LotesTrelew[[#This Row],[Final deseado / unidad sugerido]]/1.3 -> 0 | H16: =IF(OR(A16="",B16="SKU no encontrado"),"",IF(INDEX(Catalogo!$H$5:$H$905,MATCH(A16,Catalogo!$A$5:$A$905,0))=0,"",INDEX(Catalogo!$H$5:$H$905,MATCH(A16,Catalogo!$A$5:$A$905,0)))) -> 8378.466 | I16: =IF(OR(N16="ELIMINAR",H16="",G16="",G16<0,C16<=0,G16*C16>H16,E16>O16),"",1-G16*C16/H16) -> 1 | J16: =IF(I16="","",H16-G16*C16) -> 8378.466 | K16: =IF(OR(J16="",E16="",E16<=0),"",J16*E16) -> 2136508.8 | L16: =IF(OR(I16="",C16<=0),"",G16*C16) -> 0 | M16: =IF(N16="ELIMINAR","ELIMINAR según origen",IF(H16="","Sin precio válido",IF(C16<=0,"Sin unidades por bulto",IF(G16="","Completar precio unitario",IF(OR(G16<0,G16*C16>H16),"Revisar precio unitario",IF(OR(E16<=0,E16>O16),"Revisar bultos vs. stock","Estimado proporcional")))))) -> Estimado proporcional | N16: ACCIONAR | O16: 255 | P16: 1 | Q16: 71 | R16: =IF(OR(H16="",C16<=0),"",H16/C16) -> 1396.411
A17: 31354 | B17: =IF(A17="","",IF(COUNTIF(Catalogo!$A$5:$A$905,A17)=0,"SKU no encontrado",INDEX(Catalogo!$B$5:$B$905,MATCH(A17,Catalogo!$A$5:$A$905,0)))) -> ANDES ORIGEN RUBIA ORO CAN 4X6 473CC | C17: =IF(OR(A17="",B17="SKU no encontrado"),"",INDEX(Catalogo!$C$5:$C$905,MATCH(A17,Catalogo!$A$5:$A$905,0))) -> 24 | D17: 46384 | E17: 362.33333 | G17: =+LotesTrelew[[#This Row],[Final deseado / unidad sugerido]]/1.3 -> 0 | H17: =IF(OR(A17="",B17="SKU no encontrado"),"",IF(INDEX(Catalogo!$H$5:$H$905,MATCH(A17,Catalogo!$A$5:$A$905,0))=0,"",INDEX(Catalogo!$H$5:$H$905,MATCH(A17,Catalogo!$A$5:$A$905,0)))) -> 57555.617 | I17: =IF(OR(N17="ELIMINAR",H17="",G17="",G17<0,C17<=0,G17*C17>H17,E17>O17),"",1-G17*C17/H17) -> 1 | J17: =IF(I17="","",H17-G17*C17) -> 57555.617 | K17: =IF(OR(J17="",E17="",E17<=0),"",J17*E17) -> 20854319 | L17: =IF(OR(I17="",C17<=0),"",G17*C17) -> 0 | M17: =IF(N17="ELIMINAR","ELIMINAR según origen",IF(H17="","Sin precio válido",IF(C17<=0,"Sin unidades por bulto",IF(G17="","Completar precio unitario",IF(OR(G17<0,G17*C17>H17),"Revisar precio unitario",IF(OR(E17<=0,E17>O17),"Revisar bultos vs. stock","Estimado proporcional")))))) -> Estimado proporcional | N17: ACCIONAR | O17: 362.33333 | P17: 1 | Q17: 96 | R17: =IF(OR(H17="",C17<=0),"",H17/C17) -> 2398.1507
... A197: 32263 | B197: =IF(A197="","",IF(COUNTIF(Catalogo!$A$5:$A$905,A197)=0,"SKU no encontrado",INDEX(Catalogo!$B$5:$B$905,MATCH(A197,Catalogo!$A$5:$A$905,0)))) -> 3P - YERBA C/P PLAYADITO X5 1KG | C197: =IF(OR(A197="",B197="SKU no encontrado"),"",INDEX(Catalogo!$C$5:$C$905,MATCH(A197,Catalogo!$A$5:$A$905,0))) -> 5 | D197: 46865 | E197: 0.4 | G197: =+LotesTrelew[[#This Row],[Final deseado / unidad sugerido]]/1.3 -> 0 | H197: =IF(OR(A197="",B197="SKU no encontrado"),"",IF(INDEX(Catalogo!$H$5:$H$905,MATCH(A197,Catalogo!$A$5:$A$905,0))=0,"",INDEX(Catalogo!$H$5:$H$905,MATCH(A197,Catalogo!$A$5:$A$905,0)))) -> 20714.312 | I197: =IF(OR(N197="ELIMINAR",H197="",G197="",G197<0,C197<=0,G197*C197>H197,E197>O197),"",1-G197*C197/H197) -> 1 | J197: =IF(I197="","",H197-G197*C197) -> 20714.312 | K197: =IF(OR(J197="",E197="",E197<=0),"",J197*E197) -> 8285.7248 | L197: =IF(OR(I197="",C197<=0),"",G197*C197) -> 0 | M197: =IF(N197="ELIMINAR","ELIMINAR según origen",IF(H197="","Sin precio válido",IF(C197<=0,"Sin unidades por bulto",IF(G197="","Completar precio unitario",IF(OR(G197<0,G197*C197>H197),"Revisar precio unitario",IF(OR(E197<=0,E197>O197),"Revisar bultos vs. stock","Estimado proporcional")))))) -> Estimado proporcional | N197: OK | O197: 0.4 | P197: 1 | Q197: 580 | R197: =IF(OR(H197="",C197<=0),"",H197/C197) -> 4142.8624
A198: 31204 | B198: =IF(A198="","",IF(COUNTIF(Catalogo!$A$5:$A$905,A198)=0,"SKU no encontrado",INDEX(Catalogo!$B$5:$B$905,MATCH(A198,Catalogo!$A$5:$A$905,0)))) -> ANDES ORIGEN RUBIA 2.0 RET X12 1000CC | C198: =IF(OR(A198="",B198="SKU no encontrado"),"",INDEX(Catalogo!$C$5:$C$905,MATCH(A198,Catalogo!$A$5:$A$905,0))) -> 12 | D198: 46284 | E198: 0.083333333 | G198: =+LotesTrelew[[#This Row],[Final deseado / unidad sugerido]]/1.3 -> 0 | H198: =IF(OR(A198="",B198="SKU no encontrado"),"",IF(INDEX(Catalogo!$H$5:$H$905,MATCH(A198,Catalogo!$A$5:$A$905,0))=0,"",INDEX(Catalogo!$H$5:$H$905,MATCH(A198,Catalogo!$A$5:$A$905,0)))) -> 47326.295 | I198: =IF(OR(N198="ELIMINAR",H198="",G198="",G198<0,C198<=0,G198*C198>H198,E198>O198),"",1-G198*C198/H198) | J198: =IF(I198="","",H198-G198*C198) | K198: =IF(OR(J198="",E198="",E198<=0),"",J198*E198) | L198: =IF(OR(I198="",C198<=0),"",G198*C198) | M198: =IF(N198="ELIMINAR","ELIMINAR según origen",IF(H198="","Sin precio válido",IF(C198<=0,"Sin unidades por bulto",IF(G198="","Completar precio unitario",IF(OR(G198<0,G198*C198>H198),"Revisar precio unitario",IF(OR(E198<=0,E198>O198),"Revisar bultos vs. stock","Estimado proporcional")))))) -> ELIMINAR según origen | N198: ELIMINAR | O198: 0.083333333 | P198: 1 | Q198: BLOQUEADO | R198: =IF(OR(H198="",C198<=0),"",H198/C198) -> 3943.8579
B199: =IF(A199="","",IF(COUNTIF(Catalogo!$A$5:$A$905,A199)=0,"SKU no encontrado",INDEX(Catalogo!$B$5:$B$905,MATCH(A199,Catalogo!$A$5:$A$905,0)))) | C199: =IF(OR(A199="",B199="SKU no encontrado"),"",INDEX(Catalogo!$C$5:$C$905,MATCH(A199,Catalogo!$A$5:$A$905,0))) | H199: =IF(OR(A199="",B199="SKU no encontrado"),"",IF(INDEX(Catalogo!$H$5:$H$905,MATCH(A199,Catalogo!$A$5:$A$905,0))=0,"",INDEX(Catalogo!$H$5:$H$905,MATCH(A199,Catalogo!$A$5:$A$905,0)))) | I199: =IF(OR(H199="",G199="",G199<0,C199<=0,G199*C199>H199),"",1-G199*C199/H199) -> #VALUE! | J199: =IF(I199="","",H199-G199*C199) -> #VALUE! | K199: =IF(OR(J199="",E199="",E199<=0),"",J199*E199) -> #VALUE! | L199: =IF(OR(I199="",C199<=0),"",G199*C199) -> #VALUE! | M199: =IF(A199="","",IF(B199="SKU no encontrado",B199,IF(H199="","Sin precio válido",IF(G199="","Completar precio deseado",IF(OR(G199<0,C199<=0,G199*C199>H199),"Revisar precio deseado",IF(OR(E199="",E199<=0),"Completar bultos","Estimado proporcional"))))))
B200: =IF(A200="","",IF(COUNTIF(Catalogo!$A$5:$A$905,A200)=0,"SKU no encontrado",INDEX(Catalogo!$B$5:$B$905,MATCH(A200,Catalogo!$A$5:$A$905,0)))) | C200: =IF(OR(A200="",B200="SKU no encontrado"),"",INDEX(Catalogo!$C$5:$C$905,MATCH(A200,Catalogo!$A$5:$A$905,0))) | H200: =IF(OR(A200="",B200="SKU no encontrado"),"",IF(INDEX(Catalogo!$H$5:$H$905,MATCH(A200,Catalogo!$A$5:$A$905,0))=0,"",INDEX(Catalogo!$H$5:$H$905,MATCH(A200,Catalogo!$A$5:$A$905,0)))) | I200: =IF(OR(H200="",G200="",G200<0,C200<=0,G200*C200>H200),"",1-G200*C200/H200) -> #VALUE! | J200: =IF(I200="","",H200-G200*C200) -> #VALUE! | K200: =IF(OR(J200="",E200="",E200<=0),"",J200*E200) -> #VALUE! | L200: =IF(OR(I200="",C200<=0),"",G200*C200) -> #VALUE! | M200: =IF(A200="","",IF(B200="SKU no encontrado",B200,IF(H200="","Sin precio válido",IF(G200="","Completar precio deseado",IF(OR(G200<0,C200<=0,G200*C200>H200),"Revisar precio deseado",IF(OR(E200="",E200<=0),"Completar bultos","Estimado proporcional"))))))
B201: =IF(A201="","",IF(COUNTIF(Catalogo!$A$5:$A$905,A201)=0,"SKU no encontrado",INDEX(Catalogo!$B$5:$B$905,MATCH(A201,Catalogo!$A$5:$A$905,0)))) | C201: =IF(OR(A201="",B201="SKU no encontrado"),"",INDEX(Catalogo!$C$5:$C$905,MATCH(A201,Catalogo!$A$5:$A$905,0))) | H201: =IF(OR(A201="",B201="SKU no encontrado"),"",IF(INDEX(Catalogo!$H$5:$H$905,MATCH(A201,Catalogo!$A$5:$A$905,0))=0,"",INDEX(Catalogo!$H$5:$H$905,MATCH(A201,Catalogo!$A$5:$A$905,0)))) | I201: =IF(OR(H201="",G201="",G201<0,C201<=0,G201*C201>H201),"",1-G201*C201/H201) -> #VALUE! | J201: Gasto cargado sucursal | K201: =SUM(K5:K198) -> 1.6324616e+09 | L201: =IF(OR(I201="",C201<=0),"",G201*C201) -> #VALUE! | M201: =IF(A201="","",IF(B201="SKU no encontrado",B201,IF(H201="","Sin precio válido",IF(G201="","Completar precio deseado",IF(OR(G201<0,C201<=0,G201*C201>H201),"Revisar precio deseado",IF(OR(E201="",E201<=0),"Completar bultos","Estimado proporcional"))))))
B202: =IF(A202="","",IF(COUNTIF(Catalogo!$A$5:$A$905,A202)=0,"SKU no encontrado",INDEX(Catalogo!$B$5:$B$905,MATCH(A202,Catalogo!$A$5:$A$905,0)))) | C202: =IF(OR(A202="",B202="SKU no encontrado"),"",INDEX(Catalogo!$C$5:$C$905,MATCH(A202,Catalogo!$A$5:$A$905,0))) | H202: =IF(OR(A202="",B202="SKU no encontrado"),"",IF(INDEX(Catalogo!$H$5:$H$905,MATCH(A202,Catalogo!$A$5:$A$905,0))=0,"",INDEX(Catalogo!$H$5:$H$905,MATCH(A202,Catalogo!$A$5:$A$905,0)))) | I202: =IF(OR(H202="",G202="",G202<0,C202<=0,G202*C202>H202),"",1-G202*C202/H202) -> #VALUE! | J202: =IF(I202="","",H202-G202*C202) -> #VALUE! | K202: =IF(OR(J202="",E202="",E202<=0),"",J202*E202) -> #VALUE! | L202: =IF(OR(I202="",C202<=0),"",G202*C202) -> #VALUE! | M202: =IF(A202="","",IF(B202="SKU no encontrado",B202,IF(H202="","Sin precio válido",IF(G202="","Completar precio deseado",IF(OR(G202<0,C202<=0,G202*C202>H202),"Revisar precio deseado",IF(OR(E202="",E202<=0),"Completar bultos","Estimado proporcional"))))))
B203: =IF(A203="","",IF(COUNTIF(Catalogo!$A$5:$A$905,A203)=0,"SKU no encontrado",INDEX(Catalogo!$B$5:$B$905,MATCH(A203,Catalogo!$A$5:$A$905,0)))) | C203: =IF(OR(A203="",B203="SKU no encontrado"),"",INDEX(Catalogo!$C$5:$C$905,MATCH(A203,Catalogo!$A$5:$A$905,0))) | H203: =IF(OR(A203="",B203="SKU no encontrado"),"",IF(INDEX(Catalogo!$H$5:$H$905,MATCH(A203,Catalogo!$A$5:$A$905,0))=0,"",INDEX(Catalogo!$H$5:$H$905,MATCH(A203,Catalogo!$A$5:$A$905,0)))) | I203: =IF(OR(H203="",G203="",G203<0,C203<=0,G203*C203>H203),"",1-G203*C203/H203) -> #VALUE! | J203: =IF(I203="","",H203-G203*C203) -> #VALUE! | K203: =IF(OR(J203="",E203="",E203<=0),"",J203*E203) -> #VALUE! | L203: =IF(OR(I203="",C203<=0),"",G203*C203) -> #VALUE! | M203: =IF(A203="","",IF(B203="SKU no encontrado",B203,IF(H203="","Sin precio válido",IF(G203="","Completar precio deseado",IF(OR(G203<0,C203<=0,G203*C203>H203),"Revisar precio deseado",IF(OR(E203="",E203<=0),"Completar bultos","Estimado proporcional"))))))
B204: =IF(A204="","",IF(COUNTIF(Catalogo!$A$5:$A$905,A204)=0,"SKU no encontrado",INDEX(Catalogo!$B$5:$B$905,MATCH(A204,Catalogo!$A$5:$A$905,0)))) | C204: =IF(OR(A204="",B204="SKU no encontrado"),"",INDEX(Catalogo!$C$5:$C$905,MATCH(A204,Catalogo!$A$5:$A$905,0))) | H204: =IF(OR(A204="",B204="SKU no encontrado"),"",IF(INDEX(Catalogo!$H$5:$H$905,MATCH(A204,Catalogo!$A$5:$A$905,0))=0,"",INDEX(Catalogo!$H$5:$H$905,MATCH(A204,Catalogo!$A$5:$A$905,0)))) | I204: =IF(OR(H204="",G204="",G204<0,C204<=0,G204*C204>H204),"",1-G204*C204/H204) -> #VALUE! | J204: =IF(I204="","",H204-G204*C204) -> #VALUE! | K204: =IF(OR(J204="",E204="",E204<=0),"",J204*E204) -> #VALUE! | L204: =IF(OR(I204="",C204<=0),"",G204*C204) -> #VALUE! | M204: =IF(A204="","",IF(B204="SKU no encontrado",B204,IF(H204="","Sin precio válido",IF(G204="","Completar precio deseado",IF(OR(G204<0,C204<=0,G204*C204>H204),"Revisar precio deseado",IF(OR(E204="",E204<=0),"Completar bultos","Estimado proporcional"))))))

Sheet Madryn
A1: Frescura Madryn: precio por unidad
A2: Ingresar precio unitario en F. Bultos en E precargados con stock del lote; ajustar si se bonifica una parte.
A4: SKU | B4: Descripción | C4: Unidades por bulto | D4: Vencimiento | E4: Bultos a descontar | F4: Final deseado / unidad | G4: Final actual / bulto | H4: Descuento requerido | I4: Importe cedido / bulto | J4: Gasto total descuento | K4: Final deseado / bulto | L4: Estado | M4: Estado frescura de origen | N4: Stock lote / bultos | O4: Orden lote en origen | P4: Días p/ bloqueo de origen | Q4: Final actual / unidad
A5: 10969 | B5: =IF(A5="","",IF(COUNTIF(Catalogo!$A$5:$A$905,A5)=0,"SKU no encontrado",INDEX(Catalogo!$B$5:$B$905,MATCH(A5,Catalogo!$A$5:$A$905,0)))) -> PATAGO AMBER - X1 BAR 20L | C5: =IF(OR(A5="",B5="SKU no encontrado"),"",INDEX(Catalogo!$C$5:$C$905,MATCH(A5,Catalogo!$A$5:$A$905,0))) -> 1 | D5: 46290 | E5: 11 | G5: =IF(OR(A5="",B5="SKU no encontrado"),"",IF(INDEX(Catalogo!$H$5:$H$905,MATCH(A5,Catalogo!$A$5:$A$905,0))=0,"",INDEX(Catalogo!$H$5:$H$905,MATCH(A5,Catalogo!$A$5:$A$905,0)))) -> 145134.34 | H5: =IF(OR(M5="ELIMINAR",G5="",F5="",F5<0,C5<=0,F5*C5>G5,E5>N5),"",1-F5*C5/G5) | I5: =IF(H5="","",G5-F5*C5) | J5: =IF(OR(I5="",E5="",E5<=0),"",I5*E5) | K5: =IF(OR(H5="",C5<=0),"",F5*C5) | L5: =IF(M5="ELIMINAR","ELIMINAR según origen",IF(G5="","Sin precio válido",IF(C5<=0,"Sin unidades por bulto",IF(F5="","Completar precio unitario",IF(OR(F5<0,F5*C5>G5),"Revisar precio unitario",IF(OR(E5<=0,E5>N5),"Revisar bultos vs. stock","Estimado proporcional")))))) -> Completar precio unitario | M5: ACCIONAR | N5: 11 | O5: 1 | P5: 5 | Q5: =IF(OR(G5="",C5<=0),"",G5/C5) -> 145134.34
